Workbook

Sheet 统一格式美化
A1: 基本数据
A2: 当日主要活动-英文总 | B2: 累储扭蛋大富翁（1/7）+联动秘藏（10/14）+联动豪杰、专武（10/21）+sp豪杰转盘（3/3）+教父秘藏（2/7）+教父传奇图纸消耗（2/2） | N2: 当日主要活动-美国
A3: 日期 | B3: 创建角色数 | C3: 去新DAU | D3: 付费DAU | E3: 付费率 | F3: ARPPU | G3: 付费总额 ($) | H3: 付费账号数 | I3: 新建当日付费数 | J3: 新建当日付费总额 | K3: 新增当日付费率 | L3: 新建当日ARPPU | N3: 日期 | O3: 创建角色数 | P3: 去新DAU | Q3: 付费DAU | R3: 付费率 | S3: ARPPU | T3: 付费总额 ($) | U3: 付费账号数 | V3: 新建当日付费数 | W3: 新建当日付费总额 | X3: 新增当日付费率 | Y3: 新建当日ARPPU
A4: =粘贴原始数据!A3 -> 0 | B4: =粘贴原始数据!B3 -> 0 | C4: =粘贴原始数据!C3 -> 0 | D4: =粘贴原始数据!D3 -> 0 | E4: =粘贴原始数据!E3 -> 0 | F4: =粘贴原始数据!F3 -> 0 | G4: =粘贴原始数据!G3 -> 0 | H4: =粘贴原始数据!H3 -> 0 | ... L4: =粘贴原始数据!L3 -> 0 | N4: =美国数据!A3 -> 0 | O4: =美国数据!B3 -> 0 | P4: =美国数据!C3 -> 0 | Q4: =美国数据!D3 -> 0 | R4: =美国数据!E3 -> 0 | S4: =美国数据!F3 -> 0 | T4: =美国数据!G3 -> 0 | U4: =美国数据!H3 -> 0 | ... Y4: =美国数据!L3 -> 0
A5: =粘贴原始数据!A4 -> 0 | B5: =粘贴原始数据!B4 -> 0 | C5: =粘贴原始数据!C4 -> 0 | D5: =粘贴原始数据!D4 -> 0 | E5: =粘贴原始数据!E4 -> 0 | F5: =粘贴原始数据!F4 -> 0 | G5: =粘贴原始数据!G4 -> 0 | H5: =粘贴原始数据!H4 -> 0 | ... L5: =粘贴原始数据!L4 -> 0 | N5: =美国数据!A4 -> 0 | O5: =美国数据!B4 -> 0 | P5: =美国数据!C4 -> 0 | Q5: =美国数据!D4 -> 0 | R5: =美国数据!E4 -> 0 | S5: =美国数据!F4 -> 0 | T5: =美国数据!G4 -> 0 | U5: =美国数据!H4 -> 0 | ... Y5: =美国数据!L4 -> 0
A6: =粘贴原始数据!A5 -> 0 | B6: =粘贴原始数据!B5 -> 0 | C6: =粘贴原始数据!C5 -> 0 | D6: =粘贴原始数据!D5 -> 0 | E6: =粘贴原始数据!E5 -> 0 | F6: =粘贴原始数据!F5 -> 0 | G6: =粘贴原始数据!G5 -> 0 | H6: =粘贴原始数据!H5 -> 0 | ... L6: =粘贴原始数据!L5 -> 0 | N6: =美国数据!A5 -> 0 | O6: =美国数据!B5 -> 0 | P6: =美国数据!C5 -> 0 | Q6: =美国数据!D5 -> 0 | R6: =美国数据!E5 -> 0 | S6: =美国数据!F5 -> 0 | T6: =美国数据!G5 -> 0 | U6: =美国数据!H5 -> 0 | ... Y6: =美国数据!L5 -> 0
A7: =粘贴原始数据!A6 -> 0 | B7: =粘贴原始数据!B6 -> 0 | C7: =粘贴原始数据!C6 -> 0 | D7: =粘贴原始数据!D6 -> 0 | E7: =粘贴原始数据!E6 -> 0 | F7: =粘贴原始数据!F6 -> 0 | G7: =粘贴原始数据!G6 -> 0 | H7: =粘贴原始数据!H6 -> 0 | ... L7: =粘贴原始数据!L6 -> 0 | N7: =美国数据!A6 -> 0 | O7: =美国数据!B6 -> 0 | P7: =美国数据!C6 -> 0 | Q7: =美国数据!D6 -> 0 | R7: =美国数据!E6 -> 0 | S7: =美国数据!F6 -> 0 | T7: =美国数据!G6 -> 0 | U7: =美国数据!H6 -> 0 | ... Y7: =美国数据!L6 -> 0
A8: =粘贴原始数据!A7 -> 0 | B8: =粘贴原始数据!B7 -> 0 | C8: =粘贴原始数据!C7 -> 0 | D8: =粘贴原始数据!D7 -> 0 | E8: =粘贴原始数据!E7 -> 0 | F8: =粘贴原始数据!F7 -> 0 | G8: =粘贴原始数据!G7 -> 0 | H8: =粘贴原始数据!H7 -> 0 | ... L8: =粘贴原始数据!L7 -> 0 | N8: =美国数据!A7 -> 0 | O8: =美国数据!B7 -> 0 | P8: =美国数据!C7 -> 0 | Q8: =美国数据!D7 -> 0 | R8: =美国数据!E7 -> 0 | S8: =美国数据!F7 -> 0 | T8: =美国数据!G7 -> 0 | U8: =美国数据!H7 -> 0 | ... Y8: =美国数据!L7 -> 0
A9: =粘贴原始数据!A8 -> 0 | B9: =粘贴原始数据!B8 -> 0 | C9: =粘贴原始数据!C8 -> 0 | D9: =粘贴原始数据!D8 -> 0 | E9: =粘贴原始数据!E8 -> 0 | F9: =粘贴原始数据!F8 -> 0 | G9: =粘贴原始数据!G8 -> 0 | H9: =粘贴原始数据!H8 -> 0 | ... L9: =粘贴原始数据!L8 -> 0 | N9: =美国数据!A8 -> 0 | O9: =美国数据!B8 -> 0 | P9: =美国数据!C8 -> 0 | Q9: =美国数据!D8 -> 0 | R9: =美国数据!E8 -> 0 | S9: =美国数据!F8 -> 0 | T9: =美国数据!G8 -> 0 | U9: =美国数据!H8 -> 0 | ... Y9: =美国数据!L8 -> 0
A10: =粘贴原始数据!A9 -> 0 | B10: =粘贴原始数据!B9 -> 0 | C10: =粘贴原始数据!C9 -> 0 | D10: =粘贴原始数据!D9 -> 0 | E10: =粘贴原始数据!E9 -> 0 | F10: =粘贴原始数据!F9 -> 0 | G10: =粘贴原始数据!G9 -> 0 | H10: =粘贴原始数据!H9 -> 0 | ... L10: =粘贴原始数据!L9 -> 0 | N10: =美国数据!A9 -> 0 | O10: =美国数据!B9 -> 0 | P10: =美国数据!C9 -> 0 | Q10: =美国数据!D9 -> 0 | R10: =美国数据!E9 -> 0 | S10: =美国数据!F9 -> 0 | T10: =美国数据!G9 -> 0 | U10: =美国数据!H9 -> 0 | ... Y10: =美国数据!L9 -> 0
A11: =粘贴原始数据!A10 -> 0 | B11: =粘贴原始数据!B10 -> 0 | C11: =粘贴原始数据!C10 -> 0 | D11: =粘贴原始数据!D10 -> 0 | E11: =粘贴原始数据!E10 -> 0 | F11: =粘贴原始数据!F10 -> 0 | G11: =粘贴原始数据!G10 -> 0 | H11: =粘贴原始数据!H10 -> 0 | ... L11: =粘贴原始数据!L10 -> 0 | N11: =美国数据!A10 -> 0 | O11: =美国数据!B10 -> 0 | P11: =美国数据!C10 -> 0 | Q11: =美国数据!D10 -> 0 | R11: =美国数据!E10 -> 0 | S11: =美国数据!F10 -> 0 | T11: =美国数据!G10 -> 0 | U11: =美国数据!H10 -> 0 | ... Y11: =美国数据!L10 -> 0
A12: =粘贴原始数据!A11 -> 0 | B12: =VALUE(粘贴原始数据!B11) -> 0 | C12: =VALUE(粘贴原始数据!C11) -> 0 | D12: =VALUE(粘贴原始数据!D11) -> 0 | E12: =E11-E10 -> 0 | F12: =F11-F10 -> 0 | G12: =VALUE(粘贴原始数据!G11) -> 0 | H12: =VALUE(粘贴原始数据!H11) -> 0 | I12: =I11-I10 -> 0 | J12: =VALUE(粘贴原始数据!J11) -> 0 | K12: =K11-K10 -> 0 | L12: =L11-L10 -> 0 | N12: =美国数据!A11 -> 0 | O12: =VALUE(美国数据!B11) -> 0 | P12: =VALUE(美国数据!C11) -> 0 | Q12: =VALUE(美国数据!D11) -> 0 | R12: =R11-R10 -> 0 | S12: =S11-S10 -> 0 | T12: =VALUE(美国数据!G11) -> 0 | U12: =VALUE(美国数据!H11) -> 0 | V12: =V11-V10 -> 0 | W12: =VALUE(美国数据!J11) -> 0 | X12: =X11-X10 -> 0 | Y12: =Y11-Y10 -> 0
A13: =粘贴原始数据!A12 -> 0 | B13: =VALUE(粘贴原始数据!B12) -> 0 | C13: =VALUE(粘贴原始数据!C12) -> 0 | D13: =VALUE(粘贴原始数据!D12) -> 0 | E13: =E11-E4 -> 0 | F13: =F11-F4 -> 0 | G13: =VALUE(粘贴原始数据!G12) -> 0 | H13: =VALUE(粘贴原始数据!H12) -> 0 | I13: =I11-I4 -> 0 | J13: =VALUE(粘贴原始数据!J12) -> 0 | K13: =K11-K4 -> 0 | L13: =L11-L4 -> 0 | N13: =美国数据!A12 -> 0 | O13: =VALUE(美国数据!B12) -> 0 | P13: =VALUE(美国数据!C12) -> 0 | Q13: =VALUE(美国数据!D12) -> 0 | R13: =R11-R4 -> 0 | S13: =S11-S4 -> 0 | T13: =VALUE(美国数据!G12) -> 0 | U13: =VALUE(美国数据!H12) -> 0 | V13: =V11-V4 -> 0 | W13: =VALUE(美国数据!J12) -> 0 | X13: =X11-X4 -> 0 | Y13: =Y11-Y4 -> 0
A16: 留存数据
A17: 日期 | B17: 总留存 | F17: Android | J17: IOS
B18: 创建数 | C18: 次留 | D18: 三留 | E18: 七留 | F18: 创建数 | G18: 次留 | H18: 三留 | I18: 七留 | J18: 创建数 | K18: 次留 | L18: 三留 | M18: 七留
A19: =粘贴原始数据!A18 -> 0 | B19: =粘贴原始数据!B18 -> 0 | C19: =VALUE(粘贴原始数据!C18) -> 0 | D19: =粘贴原始数据!D18 -> 0 | E19: =粘贴原始数据!E18 -> 0 | F19: =粘贴原始数据!B29 -> 0 | G19: =VALUE(粘贴原始数据!C29) -> 0 | H19: =粘贴原始数据!D29 -> 0 | I19: =粘贴原始数据!E29 -> 0 | J19: =粘贴原始数据!F29 -> 0 | K19: =VALUE(粘贴原始数据!G29) -> 0 | L19: =粘贴原始数据!H29 -> 0 | M19: =粘贴原始数据!I29 -> 0
A20: =粘贴原始数据!A19 -> 0 | B20: =粘贴原始数据!B19 -> 0 | C20: =VALUE(粘贴原始数据!C19) -> 0 | D20: =粘贴原始数据!D19 -> 0 | E20: =粘贴原始数据!E19 -> 0 | F20: =粘贴原始数据!B30 -> 0 | G20: =VALUE(粘贴原始数据!C30) -> 0 | H20: =粘贴原始数据!D30 -> 0 | I20: =粘贴原始数据!E30 -> 0 | J20: =粘贴原始数据!F30 -> 0 | K20: =VALUE(粘贴原始数据!G30) -> 0 | L20: =粘贴原始数据!H30 -> 0 | M20: =粘贴原始数据!I30 -> 0
A21: =粘贴原始数据!A20 -> 0 | B21: =粘贴原始数据!B20 -> 0 | C21: =VALUE(粘贴原始数据!C20) -> 0 | D21: =粘贴原始数据!D20 -> 0 | E21: =粘贴原始数据!E20 -> 0 | F21: =粘贴原始数据!B31 -> 0 | G21: =VALUE(粘贴原始数据!C31) -> 0 | H21: =粘贴原始数据!D31 -> 0 | I21: =粘贴原始数据!E31 -> 0 | J21: =粘贴原始数据!F31 -> 0 | K21: =VALUE(粘贴原始数据!G31) -> 0 | L21: =粘贴原始数据!H31 -> 0 | M21: =粘贴原始数据!I31 -> 0
A22: =粘贴原始数据!A21 -> 0 | B22: =粘贴原始数据!B21 -> 0 | C22: =VALUE(粘贴原始数据!C21) -> 0 | D22: =粘贴原始数据!D21 -> 0 | E22: =粘贴原始数据!E21 -> 0 | F22: =粘贴原始数据!B32 -> 0 | G22: =VALUE(粘贴原始数据!C32) -> 0 | H22: =粘贴原始数据!D32 -> 0 | I22: =粘贴原始数据!E32 -> 0 | J22: =粘贴原始数据!F32 -> 0 | K22: =VALUE(粘贴原始数据!G32) -> 0 | L22: =粘贴原始数据!H32 -> 0 | M22: =粘贴原始数据!I32 -> 0
A23: =粘贴原始数据!A22 -> 0 | B23: =粘贴原始数据!B22 -> 0 | C23: =VALUE(粘贴原始数据!C22) -> 0 | D23: =粘贴原始数据!D22 -> 0 | E23: =粘贴原始数据!E22 -> 0 | F23: =粘贴原始数据!B33 -> 0 | G23: =VALUE(粘贴原始数据!C33) -> 0 | H23: =粘贴原始数据!D33 -> 0 | I23: =粘贴原始数据!E33 -> 0 | J23: =粘贴原始数据!F33 -> 0 | K23: =VALUE(粘贴原始数据!G33) -> 0 | L23: =粘贴原始数据!H33 -> 0 | M23: =粘贴原始数据!I33 -> 0
A24: =粘贴原始数据!A23 -> 0 | B24: =粘贴原始数据!B23 -> 0 | C24: =VALUE(粘贴原始数据!C23) -> 0 | D24: =粘贴原始数据!D23 -> 0 | E24: =粘贴原始数据!E23 -> 0 | F24: =粘贴原始数据!B34 -> 0 | G24: =VALUE(粘贴原始数据!C34) -> 0 | H24: =粘贴原始数据!D34 -> 0 | I24: =粘贴原始数据!E34 -> 0 | J24: =粘贴原始数据!F34 -> 0 | K24: =VALUE(粘贴原始数据!G34) -> 0 | L24: =粘贴原始数据!H34 -> 0 | M24: =粘贴原始数据!I34 -> 0
A25: =粘贴原始数据!A24 -> 0 | B25: =粘贴原始数据!B24 -> 0 | C25: =VALUE(粘贴原始数据!C24) -> 0 | D25: =粘贴原始数据!D24 -> 0 | E25: =粘贴原始数据!E24 -> 0 | F25: =粘贴原始数据!B35 -> 0 | G25: =VALUE(粘贴原始数据!C35) -> 0 | H25: =粘贴原始数据!D35 -> 0 | I25: =粘贴原始数据!E35 -> 0 | J25: =粘贴原始数据!F35 -> 0 | K25: =VALUE(粘贴原始数据!G35) -> 0 | L25: =粘贴原始数据!H35 -> 0 | M25: =粘贴原始数据!I35 -> 0
A26: =粘贴原始数据!A25 -> 0 | B26: =粘贴原始数据!B25 -> 0 | C26: =粘贴原始数据!C25 -> 0 | D26: =粘贴原始数据!D25 -> 0 | E26: =粘贴原始数据!E25 -> 0 | F26: =粘贴原始数据!B36 -> 0 | G26: =粘贴原始数据!C36 -> 0 | H26: =粘贴原始数据!D36 -> 0 | I26: =粘贴原始数据!E36 -> 0 | J26: =粘贴原始数据!F36 -> 0 | K26: =粘贴原始数据!G36 -> 0 | L26: =粘贴原始数据!H36 -> 0 | M26: =粘贴原始数据!I36 -> 0
F27: =(F26-F25)/F25 -> #DIV/0! | J27: =(J26-J25)/J25 -> #DIV/0!
A28: 日期 | B28: 自然量 | F28: 非激励量渠道 | J28: 激励量渠道
B29: 创建数 | C29: 次留 | D29: 三留 | E29: 七留 | F29: 创建数 | G29: 次留 | H29: 三留 | I29: 七留 | J29: 创建数 | K29: 次留 | L29: 三留 | M29: 七留
A30: =粘贴原始数据!A40 -> 0 | B30: =粘贴原始数据!B40 -> 0 | C30: =VALUE(粘贴原始数据!C40) -> 0 | D30: =粘贴原始数据!D40 -> 0 | E30: =粘贴原始数据!E40 -> 0 | F30: =粘贴原始数据!F40 -> 0 | G30: =VALUE(粘贴原始数据!G40) -> 0 | H30: =粘贴原始数据!H40 -> 0 | I30: =粘贴原始数据!I40 -> 0 | J30: =粘贴原始数据!J40 -> 0 | K30: =VALUE(粘贴原始数据!K40) -> 0 | L30: =粘贴原始数据!L40 -> 0 | M30: =粘贴原始数据!M40 -> 0
A31: =粘贴原始数据!A41 -> 0 | B31: =粘贴原始数据!B41 -> 0 | C31: =VALUE(粘贴原始数据!C41) -> 0 | D31: =粘贴原始数据!D41 -> 0 | E31: =粘贴原始数据!E41 -> 0 | F31: =粘贴原始数据!F41 -> 0 | G31: =VALUE(粘贴原始数据!G41) -> 0 | H31: =粘贴原始数据!H41 -> 0 | I31: =粘贴原始数据!I41 -> 0 | J31: =粘贴原始数据!J41 -> 0 | K31: =VALUE(粘贴原始数据!K41) -> 0 | L31: =粘贴原始数据!L41 -> 0 | M31: =粘贴原始数据!M41 -> 0
A32: =粘贴原始数据!A42 -> 0 | B32: =粘贴原始数据!B42 -> 0 | C32: =VALUE(粘贴原始数据!C42) -> 0 | D32: =粘贴原始数据!D42 -> 0 | E32: =粘贴原始数据!E42 -> 0 | F32: =粘贴原始数据!F42 -> 0 | G32: =VALUE(粘贴原始数据!G42) -> 0 | H32: =粘贴原始数据!H42 -> 0 | I32: =粘贴原始数据!I42 -> 0 | J32: =粘贴原始数据!J42 -> 0 | K32: =VALUE(粘贴原始数据!K42) -> 0 | L32: =粘贴原始数据!L42 -> 0 | M32: =粘贴原始数据!M42 -> 0
A33: =粘贴原始数据!A43 -> 0 | B33: =粘贴原始数据!B43 -> 0 | C33: =VALUE(粘贴原始数据!C43) -> 0 | D33: =粘贴原始数据!D43 -> 0 | E33: =粘贴原始数据!E43 -> 0 | F33: =粘贴原始数据!F43 -> 0 | G33: =VALUE(粘贴原始数据!G43) -> 0 | H33: =粘贴原始数据!H43 -> 0 | I33: =粘贴原始数据!I43 -> 0 | J33: =粘贴原始数据!J43 -> 0 | K33: =VALUE(粘贴原始数据!K43) -> 0 | L33: =粘贴原始数据!L43 -> 0 | M33: =粘贴原始数据!M43 -> 0
A34: =粘贴原始数据!A44 -> 0 | B34: =粘贴原始数据!B44 -> 0 | C34: =VALUE(粘贴原始数据!C44) -> 0 | D34: =粘贴原始数据!D44 -> 0 | E34: =粘贴原始数据!E44 -> 0 | F34: =粘贴原始数据!F44 -> 0 | G34: =VALUE(粘贴原始数据!G44) -> 0 | H34: =粘贴原始数据!H44 -> 0 | I34: =粘贴原始数据!I44 -> 0 | J34: =粘贴原始数据!J44 -> 0 | K34: =VALUE(粘贴原始数据!K44) -> 0 | L34: =粘贴原始数据!L44 -> 0 | M34: =粘贴原始数据!M44 -> 0
A35: =粘贴原始数据!A45 -> 0 | B35: =粘贴原始数据!B45 -> 0 | C35: =VALUE(粘贴原始数据!C45) -> 0 | D35: =粘贴原始数据!D45 -> 0 | E35: =粘贴原始数据!E45 -> 0 | F35: =粘贴原始数据!F45 -> 0 | G35: =VALUE(粘贴原始数据!G45) -> 0 | H35: =粘贴原始数据!H45 -> 0 | I35: =粘贴原始数据!I45 -> 0 | J35: =粘贴原始数据!J45 -> 0 | K35: =VALUE(粘贴原始数据!K45) -> 0 | L35: =粘贴原始数据!L45 -> 0 | M35: =粘贴原始数据!M45 -> 0
A36: =粘贴原始数据!A46 -> 0 | B36: =粘贴原始数据!B46 -> 0 | C36: =VALUE(粘贴原始数据!C46) -> 0 | D36: =粘贴原始数据!D46 -> 0 | E36: =粘贴原始数据!E46 -> 0 | F36: =粘贴原始数据!F46 -> 0 | G36: =VALUE(粘贴原始数据!G46) -> 0 | H36: =粘贴原始数据!H46 -> 0 | I36: =粘贴原始数据!I46 -> 0 | J36: =粘贴原始数据!J46 -> 0 | K36: =VALUE(粘贴原始数据!K46) -> 0 | L36: =粘贴原始数据!L46 -> 0 | M36: =粘贴原始数据!M46 -> 0
A37: =粘贴原始数据!A47 -> 0 | B37: =粘贴原始数据!B47 -> 0 | C37: =粘贴原始数据!C47 -> 0 | D37: =粘贴原始数据!D47 -> 0 | E37: =粘贴原始数据!E47 -> 0 | F37: =粘贴原始数据!F47 -> 0 | G37: =粘贴原始数据!G47 -> 0 | H37: =粘贴原始数据!H47 -> 0 | ... M37: =粘贴原始数据!M47 -> 0
A40: 礼包销量总览
A41: 日期 | B41: 0.99 | C41: 1.99 | D41: 2.99 | E41: 4.99 | F41: 9.99 | G41: 19.99 | H41: 24.99 | I41: 49.99 | J41: 79.99 | K41: 99.99
A42: =粘贴原始数据!A52 -> 0 | B42: =粘贴原始数据!B52 -> 0 | C42: =粘贴原始数据!C52 -> 0 | D42: =粘贴原始数据!D52 -> 0 | E42: =粘贴原始数据!E52 -> 0 | F42: =粘贴原始数据!F52 -> 0 | G42: =粘贴原始数据!G52 -> 0 | H42: =粘贴原始数据!H52 -> 0 | ... K42: =粘贴原始数据!K52 -> 0
A43: =粘贴原始数据!A53 -> 0 | B43: =粘贴原始数据!B53 -> 0 | C43: =粘贴原始数据!C53 -> 0 | D43: =粘贴原始数据!D53 -> 0 | E43: =粘贴原始数据!E53 -> 0 | F43: =粘贴原始数据!F53 -> 0 | G43: =粘贴原始数据!G53 -> 0 | H43: =粘贴原始数据!H53 -> 0 | ... K43: =粘贴原始数据!K53 -> 0
A44: =粘贴原始数据!A54 -> 0 | B44: =粘贴原始数据!B54 -> 0 | C44: =粘贴原始数据!C54 -> 0 | D44: =粘贴原始数据!D54 -> 0 | E44: =粘贴原始数据!E54 -> 0 | F44: =粘贴原始数据!F54 -> 0 | G44: =粘贴原始数据!G54 -> 0 | H44: =粘贴原始数据!H54 -> 0 | ... K44: =粘贴原始数据!K54 -> 0
...

Sheet 粘贴原始数据

Sheet 美国数据
